Unable to init server: Could not connect: Connection refused
Unable to init server: Could not connect: Connection refused

(main.py:2721739): Gdk-CRITICAL **: 23:25:42.915: gdk_cursor_new_for_display: assertion 'GDK_IS_DISPLAY (display)' failed

(main.py:2721739): Gdk-CRITICAL **: 23:25:42.915: gdk_cursor_new_for_display: assertion 'GDK_IS_DISPLAY (display)' failed
49900
88789
144633
207847
256627
Traceback (most recent call last):
  File "main.py", line 373, in <module>
    enda = ((temp[0][0][0]+temp[0][1][0])/2,(temp[0][0][1]+temp[0][1][1])/2)
IndexError: list index out of range
